2025-08-08 00:00:47,851 - main - INFO - Starting Algorithmic Trading System - Test Mode
2025-08-08 00:00:49,328 - main - INFO - Successfully processed data for 3 stocks
2025-08-08 00:00:49,328 - main - INFO - Running backtests on processed data
2025-08-08 00:00:49,328 - main - INFO - Running backtest for RELIANCE.NS
2025-08-08 00:00:49,370 - main - INFO - Running backtest for TCS.NS
2025-08-08 00:00:49,413 - main - INFO - Running backtest for HDFCBANK.NS
2025-08-08 00:00:49,454 - main - INFO - Test execution completed successfully
2025-08-08 00:04:10,939 - main - INFO - Starting Algorithmic Trading System - Test Mode
2025-08-08 00:04:12,589 - main - INFO - Successfully processed data for 3 stocks
2025-08-08 00:04:12,589 - main - INFO - Running backtests on processed data
2025-08-08 00:04:12,589 - main - INFO - Running backtest for RELIANCE.NS
2025-08-08 00:04:12,601 - main - ERROR - Error during execution: unsupported format string passed to Series.__format__
2025-08-08 00:04:12,601 - main - ERROR - Traceback (most recent call last):
  File "/home/anwesh2410/IITJ/Proj/Assignments/Algo-Trading System/algo_trading_system/src/main.py", line 38, in main
    backtest_results = run_backtests(processed_data)
                       ^^^^^^^^^^^^^^^^^^^^^^^^^^^^^
  File "/home/anwesh2410/IITJ/Proj/Assignments/Algo-Trading System/algo_trading_system/src/main.py", line 71, in run_backtests
    backtest_data, trades, metrics = backtest.run_backtest(data, symbol)
                                     ^^^^^^^^^^^^^^^^^^^^^^^^^^^^^^^^^^^
  File "/home/anwesh2410/IITJ/Proj/Assignments/Algo-Trading System/algo_trading_system/src/strategies/backtest.py", line 89, in run_backtest
    logger.info(f"SELL signal for {symbol} at {exit_date}: {exit_price}, P&L: {pnl:.2f}%")
                ^^^^^^^^^^^^^^^^^^^^^^^^^^^^^^^^^^^^^^^^^^^^^^^^^^^^^^^^^^^^^^^^^^^^^^^^^
TypeError: unsupported format string passed to Series.__format__

2025-08-08 00:05:55,376 - main - INFO - Starting Algorithmic Trading System - Test Mode
2025-08-08 00:05:55,417 - main - INFO - Successfully processed data for 3 stocks
2025-08-08 00:05:55,417 - main - INFO - Running backtests on processed data
2025-08-08 00:05:55,417 - main - INFO - Running backtest for RELIANCE.NS
2025-08-08 00:06:02,478 - main - INFO - Running backtest for TCS.NS
2025-08-08 00:06:02,722 - main - INFO - Running backtest for HDFCBANK.NS
2025-08-08 00:06:02,961 - main - ERROR - Error during execution: name 'Config' is not defined
2025-08-08 00:06:02,962 - main - ERROR - Traceback (most recent call last):
  File "/home/anwesh2410/IITJ/Proj/Assignments/Algo-Trading System/algo_trading_system/src/main.py", line 43, in main
    analyze_no_trades(processed_data)
  File "/home/anwesh2410/IITJ/Proj/Assignments/Algo-Trading System/algo_trading_system/src/main.py", line 119, in analyze_no_trades
    rsi_opportunities = len(data[data['RSI'] < Config.RSI_BUY_THRESHOLD])
                                               ^^^^^^
NameError: name 'Config' is not defined

2025-08-08 00:20:51,197 - main - INFO - Starting Algorithmic Trading System - Test Mode
2025-08-08 00:20:51,242 - main - INFO - Successfully processed data for 3 stocks
2025-08-08 00:20:51,242 - main - INFO - Running backtests on processed data
2025-08-08 00:20:51,242 - main - INFO - Running backtest for RELIANCE.NS
2025-08-08 00:20:51,529 - main - INFO - Running backtest for TCS.NS
2025-08-08 00:20:51,771 - main - INFO - Running backtest for HDFCBANK.NS
2025-08-08 00:20:52,007 - main - ERROR - Error during execution: 'PnL'
2025-08-08 00:20:52,068 - main - ERROR - Traceback (most recent call last):
  File "/home/anwesh2410/anaconda3/lib/python3.11/site-packages/pandas/core/indexes/base.py", line 3790, in get_loc
    return self._engine.get_loc(casted_key)
           ^^^^^^^^^^^^^^^^^^^^^^^^^^^^^^^^
  File "index.pyx", line 152, in pandas._libs.index.IndexEngine.get_loc
  File "index.pyx", line 181, in pandas._libs.index.IndexEngine.get_loc
  File "pandas/_libs/hashtable_class_helper.pxi", line 7080, in pandas._libs.hashtable.PyObjectHashTable.get_item
  File "pandas/_libs/hashtable_class_helper.pxi", line 7088, in pandas._libs.hashtable.PyObjectHashTable.get_item
KeyError: 'PnL'

The above exception was the direct cause of the following exception:

Traceback (most recent call last):
  File "/home/anwesh2410/IITJ/Proj/Assignments/Algo-Trading System/algo_trading_system/src/main.py", line 44, in main
    analyze_no_trades(processed_data)
  File "/home/anwesh2410/IITJ/Proj/Assignments/Algo-Trading System/algo_trading_system/src/main.py", line 132, in analyze_no_trades
    profitable_trades = data[data['PnL'] > 0]['PnL'].count()
                             ~~~~^^^^^^^
  File "/home/anwesh2410/anaconda3/lib/python3.11/site-packages/pandas/core/frame.py", line 3895, in __getitem__
    return self._getitem_multilevel(key)
           ^^^^^^^^^^^^^^^^^^^^^^^^^^^^^
  File "/home/anwesh2410/anaconda3/lib/python3.11/site-packages/pandas/core/frame.py", line 3953, in _getitem_multilevel
    loc = self.columns.get_loc(key)
          ^^^^^^^^^^^^^^^^^^^^^^^^^
  File "/home/anwesh2410/anaconda3/lib/python3.11/site-packages/pandas/core/indexes/multi.py", line 2925, in get_loc
    loc = self._get_level_indexer(key, level=0)
          ^^^^^^^^^^^^^^^^^^^^^^^^^^^^^^^^^^^^^
  File "/home/anwesh2410/anaconda3/lib/python3.11/site-packages/pandas/core/indexes/multi.py", line 3276, in _get_level_indexer
    idx = self._get_loc_single_level_index(level_index, key)
          ^^^^^^^^^^^^^^^^^^^^^^^^^^^^^^^^^^^^^^^^^^^^^^^^^^
  File "/home/anwesh2410/anaconda3/lib/python3.11/site-packages/pandas/core/indexes/multi.py", line 2865, in _get_loc_single_level_index
    return level_index.get_loc(key)
           ^^^^^^^^^^^^^^^^^^^^^^^^
  File "/home/anwesh2410/anaconda3/lib/python3.11/site-packages/pandas/core/indexes/base.py", line 3797, in get_loc
    raise KeyError(key) from err
KeyError: 'PnL'

2025-08-08 00:23:11,316 - main - INFO - Starting Algorithmic Trading System - Test Mode
2025-08-08 00:23:11,358 - main - INFO - Successfully processed data for 3 stocks
2025-08-08 00:23:11,358 - main - INFO - Running backtests on processed data
2025-08-08 00:23:11,359 - main - INFO - Running backtest for RELIANCE.NS
2025-08-08 00:23:11,626 - main - INFO - Running backtest for TCS.NS
2025-08-08 00:23:11,855 - main - INFO - Running backtest for HDFCBANK.NS
2025-08-08 00:23:12,092 - main - INFO - Test execution completed successfully
